Workbook

Sheet Harian 2024
A1: PENGELOLAAN LINEN INSTALASI LAUNDRY
A2: RSJD Dr RM SOEDJARWADI PROVINSI JAWA TENGAH
A3: TAHUN 2026
A5: NO | B5: TANGGAL | C5: JENIS LINEN | D5: ANGGREK | E5: BOUGENVIL | F5: CAMELIA | G5: DEWANDARU | H5: EDELWEIS | I5: FLAMBOYAN | J5: GERANIUM | K5: HELIKONIA | L5: IVY | M5: JASMIN | N5: IGD | O5: HCU | P5: PENUNJANG | Q5: PELAYANAN | R5: ADMIN | S5: ASRAMA | T5: MASJID | U5: JUMLAH
A6: 1 | B6: KAMIS | C6: BAJU | G6: 14 | H6: 29 | I6: 29 | J6: 29 | K6: 33 | L6: 9 | M6: 2 | O6: 9 | P6: 15 | Q6: 18 | U6: =SUM(D6:T6) -> 187
B7: 46023 | C7: CELANA | G7: 14 | H7: 29 | I7: 29 | J7: 29 | K7: 33 | L7: 9 | M7: 2 | O7: 8 | P7: 3 | Q7: 18 | U7: =SUM(D7:T7) -> 174
C8: HANDUK | E8: 3 | G8: 15 | H8: 18 | I8: 16 | J8: 19 | K8: 18 | L8: 5 | M8: 1 | O8: 6 | P8: 6 | Q8: 9 | U8: =SUM(D8:T8) -> 116
C9: SPREI | D9: 6 | E9: 10 | F9: 9 | G9: 16 | H9: 30 | I9: 34 | J9: 27 | K9: 30 | L9: 8 | M9: 7 | N9: 16 | O9: 8 | P9: 5 | Q9: 6 | R9: 7 | U9: =SUM(D9:T9) -> 219
C10: SELIMUT | D10: 6 | E10: 10 | F10: 8 | G10: 28 | H10: 28 | I10: 32 | J10: 34 | K10: 25 | L10: 7 | M10: 7 | N10: 16 | O10: 4 | P10: 4 | Q10: 8 | R10: 8 | U10: =SUM(D10:T10) -> 225
C11: SARUNG BANTAL | D11: 9 | E11: 9 | F11: 6 | G11: 26 | H11: 36 | I11: 33 | J11: 34 | K11: 35 | L11: 6 | M11: 7 | N11: 20 | O11: 7 | P11: 7 | Q11: 7 | R11: 9 | U11: =SUM(D11:T11) -> 251
C12: STIK LAKEN LAKEN | D12: 7 | E12: 9 | F12: 5 | M12: 4 | U12: =SUM(D12:T12) -> 25
C13: PERLAK | D13: 7 | E13: 8 | M13: 6 | N13: 6 | U13: =SUM(D13:T13) -> 27
C14: DLL | E14: 3 | F14: 7 | G14: 12 | H14: 19 | I14: 12 | J14: 13 | K14: 8 | L14: 2 | N14: 15 | O14: 4 | Q14: 14 | U14: =SUM(D14:T14) -> 109
C15: SUB JUMLAH | D15: =SUM(D6:D14) -> 35 | E15: =SUM(E6:E14) -> 52 | F15: =SUM(F6:F14) -> 35 | G15: =SUM(G6:G14) -> 125 | H15: =SUM(H6:H14) -> 189 | I15: =SUM(I6:I14) -> 185 | J15: =SUM(J6:J14) -> 185 | K15: =SUM(K6:K14) -> 182 | ... U15: =SUM(U6:U14) -> 1333
A18: NO | B18: TANGGAL | C18: JENIS LINEN | D18: =D5 -> ANGGREK | E18: =E5 -> BOUGENVIL | F18: =F5 -> CAMELIA | G18: =G5 -> DEWANDARU | H18: =H5 -> EDELWEIS | I18: =I5 -> FLAMBOYAN | J18: =J5 -> GERANIUM | K18: =K5 -> HELIKONIA | ... U18: =U5 -> JUMLAH
A19: =A6+1 -> 2 | B19: JUMAT | C19: BAJU | G19: 28 | H19: 27 | I19: 29 | J19: 29 | K19: 31 | L19: 10 | O19: 3 | P19: 7 | Q19: 2 | U19: =SUM(D19:T19) -> 166
B20: =B7+1 -> 46024 | C20: CELANA | G20: 28 | H20: 27 | I20: 29 | J20: 29 | K20: 31 | L20: 10 | U20: =SUM(D20:T20) -> 154
C21: HANDUK | F21: 2 | G21: 13 | H21: 19 | I21: 19 | J21: 19 | K21: 18 | L21: 8 | O21: 4 | P21: 2 | Q21: 8 | U21: =SUM(D21:T21) -> 112
C22: SPREI | D22: 2 | E22: 4 | F22: 3 | G22: 25 | H22: 28 | I22: 32 | J22: 24 | K22: 29 | L22: 7 | M22: 7 | N22: 8 | O22: 2 | P22: 2 | Q22: 12 | U22: =SUM(D22:T22) -> 185
C23: SELIMUT | D23: 2 | E23: 3 | F23: 2 | G23: 27 | H23: 23 | I23: 25 | J23: 26 | K23: 27 | L23: 4 | M23: 7 | N23: 4 | O23: 2 | P23: 1 | Q23: 1 | U23: =SUM(D23:T23) -> 154
C24: SLOP BANTAL | D24: 2 | E24: 4 | F24: 5 | G24: 25 | H24: 32 | I24: 27 | J24: 33 | K24: 33 | L24: 6 | M24: 7 | N24: 14 | O24: 2 | P24: 2 | Q24: 11 | U24: =SUM(D24:T24) -> 203
C25: STIK LAKEN | D25: 10 | E25: 7 | F25: 3 | M25: 4 | N25: 16 | O25: 2 | U25: =SUM(D25:T25) -> 42
C26: PERLAK | D26: 7 | E26: 8 | M26: 6 | N26: 2 | U26: =SUM(D26:T26) -> 23
C27: DLL | F27: 3 | G27: 16 | H27: 8 | I27: 9 | J27: 7 | K27: 5 | L27: 5 | M27: 15 | N27: 5 | O27: 3 | T27: 25 | U27: =SUM(D27:T27) -> 101
C28: SUB JUMLAH | D28: =SUM(D19:D27) -> 23 | E28: =SUM(E19:E27) -> 26 | F28: =SUM(F19:F27) -> 18 | G28: =SUM(G19:G27) -> 162 | H28: =SUM(H19:H27) -> 164 | I28: =SUM(I19:I27) -> 170 | J28: =SUM(J19:J27) -> 167 | K28: =SUM(K19:K27) -> 174 | ... U28: =SUM(U19:U27) -> 1140
A31: NO | B31: TANGGAL | C31: JENIS LINEN | D31: =D5 -> ANGGREK | E31: =E5 -> BOUGENVIL | F31: =F5 -> CAMELIA | G31: =G5 -> DEWANDARU | H31: =H5 -> EDELWEIS | I31: =I5 -> FLAMBOYAN | J31: =J5 -> GERANIUM | K31: =K5 -> HELIKONIA | ... U31: =U5 -> JUMLAH
A32: =A19+1 -> 3 | B32: SABTU | C32: BAJU | G32: 19 | H32: 19 | I32: 28 | J32: 29 | K32: 30 | L32: 8 | M32: 2 | O32: 10 | P32: 12 | Q32: 4 | U32: =SUM(D32:T32) -> 161
B33: =B20+1 -> 46025 | C33: CELANA | G33: 19 | H33: 18 | I33: 28 | J33: 29 | K33: 30 | L33: 9 | M33: 2 | U33: =SUM(D33:T33) -> 135
C34: HANDUK | G34: 9 | H34: 8 | I34: 9 | J34: 10 | K34: 9 | L34: 4 | M34: 1 | O34: 3 | U34: =SUM(D34:T34) -> 53
C35: SPREI | D35: 3 | E35: 13 | F35: 4 | G35: 21 | H35: 28 | I35: 22 | J35: 26 | K35: 21 | L35: 10 | M35: 2 | N35: 15 | O35: 1 | P35: 3 | Q35: 3 | R35: 4 | U35: =SUM(D35:T35) -> 176
C36: SELIMUT | D36: 2 | E36: 10 | F36: 5 | G36: 19 | H36: 22 | I36: 21 | J36: 25 | K36: 25 | L36: 2 | M36: 3 | N36: 15 | O36: 1 | P36: 2 | Q36: 2 | R36: 5 | U36: =SUM(D36:T36) -> 159
C37: SLOP BANTAL | D37: 1 | E37: 20 | F37: 3 | G37: 23 | H37: 32 | I37: 25 | J37: 35 | K37: 33 | L37: 6 | M37: 5 | N37: 9 | P37: 2 | Q37: 1 | R37: 3 | U37: =SUM(D37:T37) -> 198
C38: STIK LAKEN | D38: 3 | E38: 12 | F38: 5 | O38: 2 | U38: =SUM(D38:T38) -> 22
C39: PERLAK | D39: 2 | E39: 13 | F39: 4 | N39: 5 | O39: 2 | U39: =SUM(D39:T39) -> 26
C40: DLL | E40: 1 | G40: 5 | H40: 32 | I40: 9 | J40: 9 | K40: 11 | L40: 7 | M40: 2 | N40: 19 | O40: 2 | U40: =SUM(D40:T40) -> 97
C41: SUB JUMLAH | D41: =SUM(D32:D40) -> 11 | E41: =SUM(E32:E40) -> 69 | F41: =SUM(F32:F40) -> 21 | G41: =SUM(G32:G40) -> 115 | H41: =SUM(H32:H40) -> 159 | I41: =SUM(I32:I40) -> 142 | J41: =SUM(J32:J40) -> 163 | K41: =SUM(K32:K40) -> 159 | ... U41: =SUM(U32:U40) -> 1027
A44: NO | B44: TANGGAL | C44: JENIS LINEN | D44: =D5 -> ANGGREK | E44: =E5 -> BOUGENVIL | F44: =F5 -> CAMELIA | G44: =G5 -> DEWANDARU | H44: =H5 -> EDELWEIS | I44: =I5 -> FLAMBOYAN | J44: =J5 -> GERANIUM | K44: =K5 -> HELIKONIA | ... U44: =U5 -> JUMLAH
A45: =A32+1 -> 4 | B45: MINGGU | C45: BAJU | G45: 22 | H45: 27 | I45: 29 | J45: 29 | K45: 30 | L45: 11 | N45: 16 | O45: 12 | P45: 15 | Q45: 12 | U45: =SUM(D45:T45) -> 203
B46: =B33+1 -> 46026 | C46: CELANA | G46: 22 | H46: 27 | I46: 29 | J46: 29 | K46: 30 | L46: 10 | N46: 3 | P46: 10 | Q46: 14 | U46: =SUM(D46:T46) -> 174
C47: HANDUK | D47: 7 | G47: 19 | H47: 17 | I47: 18 | J47: 18 | K47: 16 | L47: 9 | N47: 5 | P47: 8 | Q47: 13 | R47: 7 | U47: =SUM(D47:T47) -> 137
...

Sheet Bulanan 2024
A1: PENGELOLAAN LINEN INSTALASI LAUNDRY (POTONG)
A2: RSJD Dr RM SOEDJARWADI PROVINSI JAWA TENGAH
A3: BULAN JANUARI 2026
A5: NO | B5: BULAN | C5: JENIS LINEN | D5: ANGGREK | E5: BOUGENVIL | F5: CAMELIA II | G5: DEWANDARU | H5: EDELWEIS | I5: FLAMBOYAN | J5: GERANIUM | K5: HELIKONIA | L5: IVY | M5: JASMINE | N5: IGD | O5: HCU | P5: PENUNJANG | Q5: PELAYANAN | R5: ADMIN | S5: ASRAMA | T5: MASJID | U5: Ʃ Masuk | V5: Ʃ Kirim | W5: SELISIH
B6: JANUARI | C6: BAJU | D6: ='Harian 2024'!D6+'Harian 2024'!D19+'Harian 2024'!D32+'Harian 2024'!D45+'Harian 2024'!D58+'Harian 2024'!D71+'Harian 2024'!D84+'Harian 2024'!D97+'Harian 2024'!D110+'Harian 2024'!D123+'Harian 2024'!D136+'Harian 2024'!D149+'Harian 2024'!D162+'Harian 2024'!D175+'Harian 2024'!D188+'Harian 2024'!D201+'Harian 2024'!D214+'Harian 2024'!D227+'Harian 2024'!D240+'Harian 2024'!D266+'Harian 2024'!D279+'Harian 2024'!D292+'Harian 2024'!D305+'Harian 2024'!D318+'Harian 2024'!D331+'Harian 2024'!D344+'Harian 2024'!D357+'Harian 2024'!D370+'Harian 2024'!D383+'Harian 2024'!D396 -> 0 | E6: ='Harian 2024'!E6+'Harian 2024'!E19+'Harian 2024'!E32+'Harian 2024'!E45+'Harian 2024'!E58+'Harian 2024'!E71+'Harian 2024'!E84+'Harian 2024'!E97+'Harian 2024'!E110+'Harian 2024'!E123+'Harian 2024'!E136+'Harian 2024'!E149+'Harian 2024'!E162+'Harian 2024'!E175+'Harian 2024'!E188+'Harian 2024'!E201+'Harian 2024'!E214+'Harian 2024'!E227+'Harian 2024'!E240+'Harian 2024'!E266+'Harian 2024'!E279+'Harian 2024'!E292+'Harian 2024'!E305+'Harian 2024'!E318+'Harian 2024'!E331+'Harian 2024'!E344+'Harian 2024'!E357+'Harian 2024'!E370+'Harian 2024'!E383+'Harian 2024'!E396 -> 3 | F6: ='Harian 2024'!F6+'Harian 2024'!F19+'Harian 2024'!F32+'Harian 2024'!F45+'Harian 2024'!F58+'Harian 2024'!F71+'Harian 2024'!F84+'Harian 2024'!F97+'Harian 2024'!F110+'Harian 2024'!F123+'Harian 2024'!F136+'Harian 2024'!F149+'Harian 2024'!F162+'Harian 2024'!F175+'Harian 2024'!F188+'Harian 2024'!F201+'Harian 2024'!F214+'Harian 2024'!F227+'Harian 2024'!F240+'Harian 2024'!F266+'Harian 2024'!F279+'Harian 2024'!F292+'Harian 2024'!F305+'Harian 2024'!F318+'Harian 2024'!F331+'Harian 2024'!F344+'Harian 2024'!F357+'Harian 2024'!F370+'Harian 2024'!F383+'Harian 2024'!F396 -> 14 | G6: ='Harian 2024'!G6+'Harian 2024'!G19+'Harian 2024'!G32+'Harian 2024'!G45+'Harian 2024'!G58+'Harian 2024'!G71+'Harian 2024'!G84+'Harian 2024'!G97+'Harian 2024'!G110+'Harian 2024'!G123+'Harian 2024'!G136+'Harian 2024'!G149+'Harian 2024'!G162+'Harian 2024'!G175+'Harian 2024'!G188+'Harian 2024'!G201+'Harian 2024'!G214+'Harian 2024'!G227+'Harian 2024'!G240+'Harian 2024'!G266+'Harian 2024'!G279+'Harian 2024'!G292+'Harian 2024'!G305+'Harian 2024'!G318+'Harian 2024'!G331+'Harian 2024'!G344+'Harian 2024'!G357+'Harian 2024'!G370+'Harian 2024'!G383+'Harian 2024'!G396 -> 674 | H6: ='Harian 2024'!H6+'Harian 2024'!H19+'Harian 2024'!H32+'Harian 2024'!H45+'Harian 2024'!H58+'Harian 2024'!H71+'Harian 2024'!H84+'Harian 2024'!H97+'Harian 2024'!H110+'Harian 2024'!H123+'Harian 2024'!H136+'Harian 2024'!H149+'Harian 2024'!H162+'Harian 2024'!H175+'Harian 2024'!H188+'Harian 2024'!H201+'Harian 2024'!H214+'Harian 2024'!H227+'Harian 2024'!H240+'Harian 2024'!H266+'Harian 2024'!H279+'Harian 2024'!H292+'Harian 2024'!H305+'Harian 2024'!H318+'Harian 2024'!H331+'Harian 2024'!H344+'Harian 2024'!H357+'Harian 2024'!H370+'Harian 2024'!H383+'Harian 2024'!H396 -> 803 | I6: ='Harian 2024'!I6+'Harian 2024'!I19+'Harian 2024'!I32+'Harian 2024'!I45+'Harian 2024'!I58+'Harian 2024'!I71+'Harian 2024'!I84+'Harian 2024'!I97+'Harian 2024'!I110+'Harian 2024'!I123+'Harian 2024'!I136+'Harian 2024'!I149+'Harian 2024'!I162+'Harian 2024'!I175+'Harian 2024'!I188+'Harian 2024'!I201+'Harian 2024'!I214+'Harian 2024'!I227+'Harian 2024'!I240+'Harian 2024'!I266+'Harian 2024'!I279+'Harian 2024'!I292+'Harian 2024'!I305+'Harian 2024'!I318+'Harian 2024'!I331+'Harian 2024'!I344+'Harian 2024'!I357+'Harian 2024'!I370+'Harian 2024'!I383+'Harian 2024'!I396 -> 857 | J6: ='Harian 2024'!J6+'Harian 2024'!J19+'Harian 2024'!J32+'Harian 2024'!J45+'Harian 2024'!J58+'Harian 2024'!J71+'Harian 2024'!J84+'Harian 2024'!J97+'Harian 2024'!J110+'Harian 2024'!J123+'Harian 2024'!J136+'Harian 2024'!J149+'Harian 2024'!J162+'Harian 2024'!J175+'Harian 2024'!J188+'Harian 2024'!J201+'Harian 2024'!J214+'Harian 2024'!J227+'Harian 2024'!J240+'Harian 2024'!J266+'Harian 2024'!J279+'Harian 2024'!J292+'Harian 2024'!J305+'Harian 2024'!J318+'Harian 2024'!J331+'Harian 2024'!J344+'Harian 2024'!J357+'Harian 2024'!J370+'Harian 2024'!J383+'Harian 2024'!J396 -> 850 | K6: ='Harian 2024'!K6+'Harian 2024'!K19+'Harian 2024'!K32+'Harian 2024'!K45+'Harian 2024'!K58+'Harian 2024'!K71+'Harian 2024'!K84+'Harian 2024'!K97+'Harian 2024'!K110+'Harian 2024'!K123+'Harian 2024'!K136+'Harian 2024'!K149+'Harian 2024'!K162+'Harian 2024'!K175+'Harian 2024'!K188+'Harian 2024'!K201+'Harian 2024'!K214+'Harian 2024'!K227+'Harian 2024'!K240+'Harian 2024'!K266+'Harian 2024'!K279+'Harian 2024'!K292+'Harian 2024'!K305+'Harian 2024'!K318+'Harian 2024'!K331+'Harian 2024'!K344+'Harian 2024'!K357+'Harian 2024'!K370+'Harian 2024'!K383+'Harian 2024'!K396 -> 953 | ... U6: ='Harian 2024'!U6+'Harian 2024'!U19+'Harian 2024'!U32+'Harian 2024'!U45+'Harian 2024'!U58+'Harian 2024'!U71+'Harian 2024'!U84+'Harian 2024'!U97+'Harian 2024'!U110+'Harian 2024'!U123+'Harian 2024'!U136+'Harian 2024'!U149+'Harian 2024'!U162+'Harian 2024'!U175+'Harian 2024'!U188+'Harian 2024'!U201+'Harian 2024'!U214+'Harian 2024'!U227+'Harian 2024'!U240+'Harian 2024'!U266+'Harian 2024'!U279+'Harian 2024'!U292+'Harian 2024'!U305+'Harian 2024'!U318+'Harian 2024'!U331+'Harian 2024'!U344+'Harian 2024'!U357+'Harian 2024'!U370+'Harian 2024'!U383+'Harian 2024'!U396 -> 5511 | V6: =U6 -> 5511 | W6: =U6-V6 -> 0
C7: CELANA | D7: ='Harian 2024'!D7+'Harian 2024'!D20+'Harian 2024'!D33+'Harian 2024'!D46+'Harian 2024'!D59+'Harian 2024'!D72+'Harian 2024'!D85+'Harian 2024'!D98+'Harian 2024'!D111+'Harian 2024'!D124+'Harian 2024'!D137+'Harian 2024'!D150+'Harian 2024'!D163+'Harian 2024'!D176+'Harian 2024'!D189+'Harian 2024'!D202+'Harian 2024'!D215+'Harian 2024'!D228+'Harian 2024'!D241+'Harian 2024'!D267+'Harian 2024'!D280+'Harian 2024'!D293+'Harian 2024'!D306+'Harian 2024'!D319+'Harian 2024'!D332+'Harian 2024'!D345+'Harian 2024'!D358+'Harian 2024'!D371+'Harian 2024'!D384+'Harian 2024'!D397 -> 0 | E7: ='Harian 2024'!E7+'Harian 2024'!E20+'Harian 2024'!E33+'Harian 2024'!E46+'Harian 2024'!E59+'Harian 2024'!E72+'Harian 2024'!E85+'Harian 2024'!E98+'Harian 2024'!E111+'Harian 2024'!E124+'Harian 2024'!E137+'Harian 2024'!E150+'Harian 2024'!E163+'Harian 2024'!E176+'Harian 2024'!E189+'Harian 2024'!E202+'Harian 2024'!E215+'Harian 2024'!E228+'Harian 2024'!E241+'Harian 2024'!E267+'Harian 2024'!E280+'Harian 2024'!E293+'Harian 2024'!E306+'Harian 2024'!E319+'Harian 2024'!E332+'Harian 2024'!E345+'Harian 2024'!E358+'Harian 2024'!E371+'Harian 2024'!E384+'Harian 2024'!E397 -> 0 | F7: ='Harian 2024'!F7+'Harian 2024'!F20+'Harian 2024'!F33+'Harian 2024'!F46+'Harian 2024'!F59+'Harian 2024'!F72+'Harian 2024'!F85+'Harian 2024'!F98+'Harian 2024'!F111+'Harian 2024'!F124+'Harian 2024'!F137+'Harian 2024'!F150+'Harian 2024'!F163+'Harian 2024'!F176+'Harian 2024'!F189+'Harian 2024'!F202+'Harian 2024'!F215+'Harian 2024'!F228+'Harian 2024'!F241+'Harian 2024'!F267+'Harian 2024'!F280+'Harian 2024'!F293+'Harian 2024'!F306+'Harian 2024'!F319+'Harian 2024'!F332+'Harian 2024'!F345+'Harian 2024'!F358+'Harian 2024'!F371+'Harian 2024'!F384+'Harian 2024'!F397 -> 5 | G7: ='Harian 2024'!G7+'Harian 2024'!G20+'Harian 2024'!G33+'Harian 2024'!G46+'Harian 2024'!G59+'Harian 2024'!G72+'Harian 2024'!G85+'Harian 2024'!G98+'Harian 2024'!G111+'Harian 2024'!G124+'Harian 2024'!G137+'Harian 2024'!G150+'Harian 2024'!G163+'Harian 2024'!G176+'Harian 2024'!G189+'Harian 2024'!G202+'Harian 2024'!G215+'Harian 2024'!G228+'Harian 2024'!G241+'Harian 2024'!G267+'Harian 2024'!G280+'Harian 2024'!G293+'Harian 2024'!G306+'Harian 2024'!G319+'Harian 2024'!G332+'Harian 2024'!G345+'Harian 2024'!G358+'Harian 2024'!G371+'Harian 2024'!G384+'Harian 2024'!G397 -> 675 | H7: ='Harian 2024'!H7+'Harian 2024'!H20+'Harian 2024'!H33+'Harian 2024'!H46+'Harian 2024'!H59+'Harian 2024'!H72+'Harian 2024'!H85+'Harian 2024'!H98+'Harian 2024'!H111+'Harian 2024'!H124+'Harian 2024'!H137+'Harian 2024'!H150+'Harian 2024'!H163+'Harian 2024'!H176+'Harian 2024'!H189+'Harian 2024'!H202+'Harian 2024'!H215+'Harian 2024'!H228+'Harian 2024'!H241+'Harian 2024'!H267+'Harian 2024'!H280+'Harian 2024'!H293+'Harian 2024'!H306+'Harian 2024'!H319+'Harian 2024'!H332+'Harian 2024'!H345+'Harian 2024'!H358+'Harian 2024'!H371+'Harian 2024'!H384+'Harian 2024'!H397 -> 802 | I7: ='Harian 2024'!I7+'Harian 2024'!I20+'Harian 2024'!I33+'Harian 2024'!I46+'Harian 2024'!I59+'Harian 2024'!I72+'Harian 2024'!I85+'Harian 2024'!I98+'Harian 2024'!I111+'Harian 2024'!I124+'Harian 2024'!I137+'Harian 2024'!I150+'Harian 2024'!I163+'Harian 2024'!I176+'Harian 2024'!I189+'Harian 2024'!I202+'Harian 2024'!I215+'Harian 2024'!I228+'Harian 2024'!I241+'Harian 2024'!I267+'Harian 2024'!I280+'Harian 2024'!I293+'Harian 2024'!I306+'Harian 2024'!I319+'Harian 2024'!I332+'Harian 2024'!I345+'Harian 2024'!I358+'Harian 2024'!I371+'Harian 2024'!I384+'Harian 2024'!I397 -> 857 | J7: ='Harian 2024'!J7+'Harian 2024'!J20+'Harian 2024'!J33+'Harian 2024'!J46+'Harian 2024'!J59+'Harian 2024'!J72+'Harian 2024'!J85+'Harian 2024'!J98+'Harian 2024'!J111+'Harian 2024'!J124+'Harian 2024'!J137+'Harian 2024'!J150+'Harian 2024'!J163+'Harian 2024'!J176+'Harian 2024'!J189+'Harian 2024'!J202+'Harian 2024'!J215+'Harian 2024'!J228+'Harian 2024'!J241+'Harian 2024'!J267+'Harian 2024'!J280+'Harian 2024'!J293+'Harian 2024'!J306+'Harian 2024'!J319+'Harian 2024'!J332+'Harian 2024'!J345+'Harian 2024'!J358+'Harian 2024'!J371+'Harian 2024'!J384+'Harian 2024'!J397 -> 852 | K7: ='Harian 2024'!K7+'Harian 2024'!K20+'Harian 2024'!K33+'Harian 2024'!K46+'Harian 2024'!K59+'Harian 2024'!K72+'Harian 2024'!K85+'Harian 2024'!K98+'Harian 2024'!K111+'Harian 2024'!K124+'Harian 2024'!K137+'Harian 2024'!K150+'Harian 2024'!K163+'Harian 2024'!K176+'Harian 2024'!K189+'Harian 2024'!K202+'Harian 2024'!K215+'Harian 2024'!K228+'Harian 2024'!K241+'Harian 2024'!K267+'Harian 2024'!K280+'Harian 2024'!K293+'Harian 2024'!K306+'Harian 2024'!K319+'Harian 2024'!K332+'Harian 2024'!K345+'Harian 2024'!K358+'Harian 2024'!K371+'Harian 2024'!K384+'Harian 2024'!K397 -> 953 | ... U7: ='Harian 2024'!U7+'Harian 2024'!U20+'Harian 2024'!U33+'Harian 2024'!U46+'Harian 2024'!U59+'Harian 2024'!U72+'Harian 2024'!U85+'Harian 2024'!U98+'Harian 2024'!U111+'Harian 2024'!U124+'Harian 2024'!U137+'Harian 2024'!U150+'Harian 2024'!U163+'Harian 2024'!U176+'Harian 2024'!U189+'Harian 2024'!U202+'Harian 2024'!U215+'Harian 2024'!U228+'Harian 2024'!U241+'Harian 2024'!U267+'Harian 2024'!U280+'Harian 2024'!U293+'Harian 2024'!U306+'Harian 2024'!U319+'Harian 2024'!U332+'Harian 2024'!U345+'Harian 2024'!U358+'Harian 2024'!U371+'Harian 2024'!U384+'Harian 2024'!U397 -> 4910 | V7: =U7 -> 4910 | W7: =U7-V7 -> 0
C8: HANDUK | D8: ='Harian 2024'!D8+'Harian 2024'!D21+'Harian 2024'!D34+'Harian 2024'!D47+'Harian 2024'!D60+'Harian 2024'!D73+'Harian 2024'!D86+'Harian 2024'!D99+'Harian 2024'!D112+'Harian 2024'!D125+'Harian 2024'!D138+'Harian 2024'!D151+'Harian 2024'!D164+'Harian 2024'!D177+'Harian 2024'!D190+'Harian 2024'!D203+'Harian 2024'!D216+'Harian 2024'!D229+'Harian 2024'!D242+'Harian 2024'!D268+'Harian 2024'!D281+'Harian 2024'!D294+'Harian 2024'!D307+'Harian 2024'!D320+'Harian 2024'!D333+'Harian 2024'!D346+'Harian 2024'!D359+'Harian 2024'!D372+'Harian 2024'!D385+'Harian 2024'!D398 -> 7 | E8: ='Harian 2024'!E8+'Harian 2024'!E21+'Harian 2024'!E34+'Harian 2024'!E47+'Harian 2024'!E60+'Harian 2024'!E73+'Harian 2024'!E86+'Harian 2024'!E99+'Harian 2024'!E112+'Harian 2024'!E125+'Harian 2024'!E138+'Harian 2024'!E151+'Harian 2024'!E164+'Harian 2024'!E177+'Harian 2024'!E190+'Harian 2024'!E203+'Harian 2024'!E216+'Harian 2024'!E229+'Harian 2024'!E242+'Harian 2024'!E268+'Harian 2024'!E281+'Harian 2024'!E294+'Harian 2024'!E307+'Harian 2024'!E320+'Harian 2024'!E333+'Harian 2024'!E346+'Harian 2024'!E359+'Harian 2024'!E372+'Harian 2024'!E385+'Harian 2024'!E398 -> 5 | F8: ='Harian 2024'!F8+'Harian 2024'!F21+'Harian 2024'!F34+'Harian 2024'!F47+'Harian 2024'!F60+'Harian 2024'!F73+'Harian 2024'!F86+'Harian 2024'!F99+'Harian 2024'!F112+'Harian 2024'!F125+'Harian 2024'!F138+'Harian 2024'!F151+'Harian 2024'!F164+'Harian 2024'!F177+'Harian 2024'!F190+'Harian 2024'!F203+'Harian 2024'!F216+'Harian 2024'!F229+'Harian 2024'!F242+'Harian 2024'!F268+'Harian 2024'!F281+'Harian 2024'!F294+'Harian 2024'!F307+'Harian 2024'!F320+'Harian 2024'!F333+'Harian 2024'!F346+'Harian 2024'!F359+'Harian 2024'!F372+'Harian 2024'!F385+'Harian 2024'!F398 -> 9 | G8: ='Harian 2024'!G8+'Harian 2024'!G21+'Harian 2024'!G34+'Harian 2024'!G47+'Harian 2024'!G60+'Harian 2024'!G73+'Harian 2024'!G86+'Harian 2024'!G99+'Harian 2024'!G112+'Harian 2024'!G125+'Harian 2024'!G138+'Harian 2024'!G151+'Harian 2024'!G164+'Harian 2024'!G177+'Harian 2024'!G190+'Harian 2024'!G203+'Harian 2024'!G216+'Harian 2024'!G229+'Harian 2024'!G242+'Harian 2024'!G268+'Harian 2024'!G281+'Harian 2024'!G294+'Harian 2024'!G307+'Harian 2024'!G320+'Harian 2024'!G333+'Harian 2024'!G346+'Harian 2024'!G359+'Harian 2024'!G372+'Harian 2024'!G385+'Harian 2024'!G398 -> 428 | H8: ='Harian 2024'!H8+'Harian 2024'!H21+'Harian 2024'!H34+'Harian 2024'!H47+'Harian 2024'!H60+'Harian 2024'!H73+'Harian 2024'!H86+'Harian 2024'!H99+'Harian 2024'!H112+'Harian 2024'!H125+'Harian 2024'!H138+'Harian 2024'!H151+'Harian 2024'!H164+'Harian 2024'!H177+'Harian 2024'!H190+'Harian 2024'!H203+'Harian 2024'!H216+'Harian 2024'!H229+'Harian 2024'!H242+'Harian 2024'!H268+'Harian 2024'!H281+'Harian 2024'!H294+'Harian 2024'!H307+'Harian 2024'!H320+'Harian 2024'!H333+'Harian 2024'!H346+'Harian 2024'!H359+'Harian 2024'!H372+'Harian 2024'!H385+'Harian 2024'!H398 -> 440 | I8: ='Harian 2024'!I8+'Harian 2024'!I21+'Harian 2024'!I34+'Harian 2024'!I47+'Harian 2024'!I60+'Harian 2024'!I73+'Harian 2024'!I86+'Harian 2024'!I99+'Harian 2024'!I112+'Harian 2024'!I125+'Harian 2024'!I138+'Harian 2024'!I151+'Harian 2024'!I164+'Harian 2024'!I177+'Harian 2024'!I190+'Harian 2024'!I203+'Harian 2024'!I216+'Harian 2024'!I229+'Harian 2024'!I242+'Harian 2024'!I268+'Harian 2024'!I281+'Harian 2024'!I294+'Harian 2024'!I307+'Harian 2024'!I320+'Harian 2024'!I333+'Harian 2024'!I346+'Harian 2024'!I359+'Harian 2024'!I372+'Harian 2024'!I385+'Harian 2024'!I398 -> 417 | J8: ='Harian 2024'!J8+'Harian 2024'!J21+'Harian 2024'!J34+'Harian 2024'!J47+'Harian 2024'!J60+'Harian 2024'!J73+'Harian 2024'!J86+'Harian 2024'!J99+'Harian 2024'!J112+'Harian 2024'!J125+'Harian 2024'!J138+'Harian 2024'!J151+'Harian 2024'!J164+'Harian 2024'!J177+'Harian 2024'!J190+'Harian 2024'!J203+'Harian 2024'!J216+'Harian 2024'!J229+'Harian 2024'!J242+'Harian 2024'!J268+'Harian 2024'!J281+'Harian 2024'!J294+'Harian 2024'!J307+'Harian 2024'!J320+'Harian 2024'!J333+'Harian 2024'!J346+'Harian 2024'!J359+'Harian 2024'!J372+'Harian 2024'!J385+'Harian 2024'!J398 -> 433 | K8: ='Harian 2024'!K8+'Harian 2024'!K21+'Harian 2024'!K34+'Harian 2024'!K47+'Harian 2024'!K60+'Harian 2024'!K73+'Harian 2024'!K86+'Harian 2024'!K99+'Harian 2024'!K112+'Harian 2024'!K125+'Harian 2024'!K138+'Harian 2024'!K151+'Harian 2024'!K164+'Harian 2024'!K177+'Harian 2024'!K190+'Harian 2024'!K203+'Harian 2024'!K216+'Harian 2024'!K229+'Harian 2024'!K242+'Harian 2024'!K268+'Harian 2024'!K281+'Harian 2024'!K294+'Harian 2024'!K307+'Harian 2024'!K320+'Harian 2024'!K333+'Harian 2024'!K346+'Harian 2024'!K359+'Harian 2024'!K372+'Harian 2024'!K385+'Harian 2024'!K398 -> 455 | ... U8: ='Harian 2024'!U8+'Harian 2024'!U21+'Harian 2024'!U34+'Harian 2024'!U47+'Harian 2024'!U60+'Harian 2024'!U73+'Harian 2024'!U86+'Harian 2024'!U99+'Harian 2024'!U112+'Harian 2024'!U125+'Harian 2024'!U138+'Harian 2024'!U151+'Harian 2024'!U164+'Harian 2024'!U177+'Harian 2024'!U190+'Harian 2024'!U203+'Harian 2024'!U216+'Harian 2024'!U229+'Harian 2024'!U242+'Harian 2024'!U268+'Harian 2024'!U281+'Harian 2024'!U294+'Harian 2024'!U307+'Harian 2024'!U320+'Harian 2024'!U333+'Harian 2024'!U346+'Harian 2024'!U359+'Harian 2024'!U372+'Harian 2024'!U385+'Harian 2024'!U398 -> 2856 | V8: =U8 -> 2856 | W8: =U8-V8 -> 0
C9: SPREI | D9: ='Harian 2024'!D9+'Harian 2024'!D22+'Harian 2024'!D35+'Harian 2024'!D48+'Harian 2024'!D61+'Harian 2024'!D74+'Harian 2024'!D87+'Harian 2024'!D100+'Harian 2024'!D113+'Harian 2024'!D126+'Harian 2024'!D139+'Harian 2024'!D152+'Harian 2024'!D165+'Harian 2024'!D178+'Harian 2024'!D191+'Harian 2024'!D204+'Harian 2024'!D217+'Harian 2024'!D230+'Harian 2024'!D243+'Harian 2024'!D269+'Harian 2024'!D282+'Harian 2024'!D295+'Harian 2024'!D308+'Harian 2024'!D321+'Harian 2024'!D334+'Harian 2024'!D347+'Harian 2024'!D360+'Harian 2024'!D373+'Harian 2024'!D386+'Harian 2024'!D399 -> 180 | E9: ='Harian 2024'!E9+'Harian 2024'!E22+'Harian 2024'!E35+'Harian 2024'!E48+'Harian 2024'!E61+'Harian 2024'!E74+'Harian 2024'!E87+'Harian 2024'!E100+'Harian 2024'!E113+'Harian 2024'!E126+'Harian 2024'!E139+'Harian 2024'!E152+'Harian 2024'!E165+'Harian 2024'!E178+'Harian 2024'!E191+'Harian 2024'!E204+'Harian 2024'!E217+'Harian 2024'!E230+'Harian 2024'!E243+'Harian 2024'!E269+'Harian 2024'!E282+'Harian 2024'!E295+'Harian 2024'!E308+'Harian 2024'!E321+'Harian 2024'!E334+'Harian 2024'!E347+'Harian 2024'!E360+'Harian 2024'!E373+'Harian 2024'!E386+'Harian 2024'!E399 -> 320 | F9: ='Harian 2024'!F9+'Harian 2024'!F22+'Harian 2024'!F35+'Harian 2024'!F48+'Harian 2024'!F61+'Harian 2024'!F74+'Harian 2024'!F87+'Harian 2024'!F100+'Harian 2024'!F113+'Harian 2024'!F126+'Harian 2024'!F139+'Harian 2024'!F152+'Harian 2024'!F165+'Harian 2024'!F178+'Harian 2024'!F191+'Harian 2024'!F204+'Harian 2024'!F217+'Harian 2024'!F230+'Harian 2024'!F243+'Harian 2024'!F269+'Harian 2024'!F282+'Harian 2024'!F295+'Harian 2024'!F308+'Harian 2024'!F321+'Harian 2024'!F334+'Harian 2024'!F347+'Harian 2024'!F360+'Harian 2024'!F373+'Harian 2024'!F386+'Harian 2024'!F399 -> 187 | G9: ='Harian 2024'!G9+'Harian 2024'!G22+'Harian 2024'!G35+'Harian 2024'!G48+'Harian 2024'!G61+'Harian 2024'!G74+'Harian 2024'!G87+'Harian 2024'!G100+'Harian 2024'!G113+'Harian 2024'!G126+'Harian 2024'!G139+'Harian 2024'!G152+'Harian 2024'!G165+'Harian 2024'!G178+'Harian 2024'!G191+'Harian 2024'!G204+'Harian 2024'!G217+'Harian 2024'!G230+'Harian 2024'!G243+'Harian 2024'!G269+'Harian 2024'!G282+'Harian 2024'!G295+'Harian 2024'!G308+'Harian 2024'!G321+'Harian 2024'!G334+'Harian 2024'!G347+'Harian 2024'!G360+'Harian 2024'!G373+'Harian 2024'!G386+'Harian 2024'!G399 -> 721 | H9: ='Harian 2024'!H9+'Harian 2024'!H22+'Harian 2024'!H35+'Harian 2024'!H48+'Harian 2024'!H61+'Harian 2024'!H74+'Harian 2024'!H87+'Harian 2024'!H100+'Harian 2024'!H113+'Harian 2024'!H126+'Harian 2024'!H139+'Harian 2024'!H152+'Harian 2024'!H165+'Harian 2024'!H178+'Harian 2024'!H191+'Harian 2024'!H204+'Harian 2024'!H217+'Harian 2024'!H230+'Harian 2024'!H243+'Harian 2024'!H269+'Harian 2024'!H282+'Harian 2024'!H295+'Harian 2024'!H308+'Harian 2024'!H321+'Harian 2024'!H334+'Harian 2024'!H347+'Harian 2024'!H360+'Harian 2024'!H373+'Harian 2024'!H386+'Harian 2024'!H399 -> 781 | I9: ='Harian 2024'!I9+'Harian 2024'!I22+'Harian 2024'!I35+'Harian 2024'!I48+'Harian 2024'!I61+'Harian 2024'!I74+'Harian 2024'!I87+'Harian 2024'!I100+'Harian 2024'!I113+'Harian 2024'!I126+'Harian 2024'!I139+'Harian 2024'!I152+'Harian 2024'!I165+'Harian 2024'!I178+'Harian 2024'!I191+'Harian 2024'!I204+'Harian 2024'!I217+'Harian 2024'!I230+'Harian 2024'!I243+'Harian 2024'!I269+'Harian 2024'!I282+'Harian 2024'!I295+'Harian 2024'!I308+'Harian 2024'!I321+'Harian 2024'!I334+'Harian 2024'!I347+'Harian 2024'!I360+'Harian 2024'!I373+'Harian 2024'!I386+'Harian 2024'!I399 -> 827 | J9: ='Harian 2024'!J9+'Harian 2024'!J22+'Harian 2024'!J35+'Harian 2024'!J48+'Harian 2024'!J61+'Harian 2024'!J74+'Harian 2024'!J87+'Harian 2024'!J100+'Harian 2024'!J113+'Harian 2024'!J126+'Harian 2024'!J139+'Harian 2024'!J152+'Harian 2024'!J165+'Harian 2024'!J178+'Harian 2024'!J191+'Harian 2024'!J204+'Harian 2024'!J217+'Harian 2024'!J230+'Harian 2024'!J243+'Harian 2024'!J269+'Harian 2024'!J282+'Harian 2024'!J295+'Harian 2024'!J308+'Harian 2024'!J321+'Harian 2024'!J334+'Harian 2024'!J347+'Harian 2024'!J360+'Harian 2024'!J373+'Harian 2024'!J386+'Harian 2024'!J399 -> 824 | K9: ='Harian 2024'!K9+'Harian 2024'!K22+'Harian 2024'!K35+'Harian 2024'!K48+'Harian 2024'!K61+'Harian 2024'!K74+'Harian 2024'!K87+'Harian 2024'!K100+'Harian 2024'!K113+'Harian 2024'!K126+'Harian 2024'!K139+'Harian 2024'!K152+'Harian 2024'!K165+'Harian 2024'!K178+'Harian 2024'!K191+'Harian 2024'!K204+'Harian 2024'!K217+'Harian 2024'!K230+'Harian 2024'!K243+'Harian 2024'!K269+'Harian 2024'!K282+'Harian 2024'!K295+'Harian 2024'!K308+'Harian 2024'!K321+'Harian 2024'!K334+'Harian 2024'!K347+'Harian 2024'!K360+'Harian 2024'!K373+'Harian 2024'!K386+'Harian 2024'!K399 -> 890 | ... U9: ='Harian 2024'!U9+'Harian 2024'!U22+'Harian 2024'!U35+'Harian 2024'!U48+'Harian 2024'!U61+'Harian 2024'!U74+'Harian 2024'!U87+'Harian 2024'!U100+'Harian 2024'!U113+'Harian 2024'!U126+'Harian 2024'!U139+'Harian 2024'!U152+'Harian 2024'!U165+'Harian 2024'!U178+'Harian 2024'!U191+'Harian 2024'!U204+'Harian 2024'!U217+'Harian 2024'!U230+'Harian 2024'!U243+'Harian 2024'!U269+'Harian 2024'!U282+'Harian 2024'!U295+'Harian 2024'!U308+'Harian 2024'!U321+'Harian 2024'!U334+'Harian 2024'!U347+'Harian 2024'!U360+'Harian 2024'!U373+'Harian 2024'!U386+'Harian 2024'!U399 -> 6126 | V9: =U9 -> 6126 | W9: =U9-V9 -> 0
C10: SELIMUT | D10: ='Harian 2024'!D10+'Harian 2024'!D23+'Harian 2024'!D36+'Harian 2024'!D49+'Harian 2024'!D62+'Harian 2024'!D75+'Harian 2024'!D88+'Harian 2024'!D101+'Harian 2024'!D114+'Harian 2024'!D127+'Harian 2024'!D140+'Harian 2024'!D153+'Harian 2024'!D166+'Harian 2024'!D179+'Harian 2024'!D192+'Harian 2024'!D205+'Harian 2024'!D218+'Harian 2024'!D231+'Harian 2024'!D244+'Harian 2024'!D270+'Harian 2024'!D283+'Harian 2024'!D296+'Harian 2024'!D309+'Harian 2024'!D322+'Harian 2024'!D335+'Harian 2024'!D348+'Harian 2024'!D361+'Harian 2024'!D374+'Harian 2024'!D387+'Harian 2024'!D400 -> 144 | E10: ='Harian 2024'!E10+'Harian 2024'!E23+'Harian 2024'!E36+'Harian 2024'!E49+'Harian 2024'!E62+'Harian 2024'!E75+'Harian 2024'!E88+'Harian 2024'!E101+'Harian 2024'!E114+'Harian 2024'!E127+'Harian 2024'!E140+'Harian 2024'!E153+'Harian 2024'!E166+'Harian 2024'!E179+'Harian 2024'!E192+'Harian 2024'!E205+'Harian 2024'!E218+'Harian 2024'!E231+'Harian 2024'!E244+'Harian 2024'!E270+'Harian 2024'!E283+'Harian 2024'!E296+'Harian 2024'!E309+'Harian 2024'!E322+'Harian 2024'!E335+'Harian 2024'!E348+'Harian 2024'!E361+'Harian 2024'!E374+'Harian 2024'!E387+'Harian 2024'!E400 -> 322 | F10: ='Harian 2024'!F10+'Harian 2024'!F23+'Harian 2024'!F36+'Harian 2024'!F49+'Harian 2024'!F62+'Harian 2024'!F75+'Harian 2024'!F88+'Harian 2024'!F101+'Harian 2024'!F114+'Harian 2024'!F127+'Harian 2024'!F140+'Harian 2024'!F153+'Harian 2024'!F166+'Harian 2024'!F179+'Harian 2024'!F192+'Harian 2024'!F205+'Harian 2024'!F218+'Harian 2024'!F231+'Harian 2024'!F244+'Harian 2024'!F270+'Harian 2024'!F283+'Harian 2024'!F296+'Harian 2024'!F309+'Harian 2024'!F322+'Harian 2024'!F335+'Harian 2024'!F348+'Harian 2024'!F361+'Harian 2024'!F374+'Harian 2024'!F387+'Harian 2024'!F400 -> 240 | G10: ='Harian 2024'!G10+'Harian 2024'!G23+'Harian 2024'!G36+'Harian 2024'!G49+'Harian 2024'!G62+'Harian 2024'!G75+'Harian 2024'!G88+'Harian 2024'!G101+'Harian 2024'!G114+'Harian 2024'!G127+'Harian 2024'!G140+'Harian 2024'!G153+'Harian 2024'!G166+'Harian 2024'!G179+'Harian 2024'!G192+'Harian 2024'!G205+'Harian 2024'!G218+'Harian 2024'!G231+'Harian 2024'!G244+'Harian 2024'!G270+'Harian 2024'!G283+'Harian 2024'!G296+'Harian 2024'!G309+'Harian 2024'!G322+'Harian 2024'!G335+'Harian 2024'!G348+'Harian 2024'!G361+'Harian 2024'!G374+'Harian 2024'!G387+'Harian 2024'!G400 -> 706 | H10: ='Harian 2024'!H10+'Harian 2024'!H23+'Harian 2024'!H36+'Harian 2024'!H49+'Harian 2024'!H62+'Harian 2024'!H75+'Harian 2024'!H88+'Harian 2024'!H101+'Harian 2024'!H114+'Harian 2024'!H127+'Harian 2024'!H140+'Harian 2024'!H153+'Harian 2024'!H166+'Harian 2024'!H179+'Harian 2024'!H192+'Harian 2024'!H205+'Harian 2024'!H218+'Harian 2024'!H231+'Harian 2024'!H244+'Harian 2024'!H270+'Harian 2024'!H283+'Harian 2024'!H296+'Harian 2024'!H309+'Harian 2024'!H322+'Harian 2024'!H335+'Harian 2024'!H348+'Harian 2024'!H361+'Harian 2024'!H374+'Harian 2024'!H387+'Harian 2024'!H400 -> 814 | I10: ='Harian 2024'!I10+'Harian 2024'!I23+'Harian 2024'!I36+'Harian 2024'!I49+'Harian 2024'!I62+'Harian 2024'!I75+'Harian 2024'!I88+'Harian 2024'!I101+'Harian 2024'!I114+'Harian 2024'!I127+'Harian 2024'!I140+'Harian 2024'!I153+'Harian 2024'!I166+'Harian 2024'!I179+'Harian 2024'!I192+'Harian 2024'!I205+'Harian 2024'!I218+'Harian 2024'!I231+'Harian 2024'!I244+'Harian 2024'!I270+'Harian 2024'!I283+'Harian 2024'!I296+'Harian 2024'!I309+'Harian 2024'!I322+'Harian 2024'!I335+'Harian 2024'!I348+'Harian 2024'!I361+'Harian 2024'!I374+'Harian 2024'!I387+'Harian 2024'!I400 -> 934 | J10: ='Harian 2024'!J10+'Harian 2024'!J23+'Harian 2024'!J36+'Harian 2024'!J49+'Harian 2024'!J62+'Harian 2024'!J75+'Harian 2024'!J88+'Harian 2024'!J101+'Harian 2024'!J114+'Harian 2024'!J127+'Harian 2024'!J140+'Harian 2024'!J153+'Harian 2024'!J166+'Harian 2024'!J179+'Harian 2024'!J192+'Harian 2024'!J205+'Harian 2024'!J218+'Harian 2024'!J231+'Harian 2024'!J244+'Harian 2024'!J270+'Harian 2024'!J283+'Harian 2024'!J296+'Harian 2024'!J309+'Harian 2024'!J322+'Harian 2024'!J335+'Harian 2024'!J348+'Harian 2024'!J361+'Harian 2024'!J374+'Harian 2024'!J387+'Harian 2024'!J400 -> 900 | K10: ='Harian 2024'!K10+'Harian 2024'!K23+'Harian 2024'!K36+'Harian 2024'!K49+'Harian 2024'!K62+'Harian 2024'!K75+'Harian 2024'!K88+'Harian 2024'!K101+'Harian 2024'!K114+'Harian 2024'!K127+'Harian 2024'!K140+'Harian 2024'!K153+'Harian 2024'!K166+'Harian 2024'!K179+'Harian 2024'!K192+'Harian 2024'!K205+'Harian 2024'!K218+'Harian 2024'!K231+'Harian 2024'!K244+'Harian 2024'!K270+'Harian 2024'!K283+'Harian 2024'!K296+'Harian 2024'!K309+'Harian 2024'!K322+'Harian 2024'!K335+'Harian 2024'!K348+'Harian 2024'!K361+'Harian 2024'!K374+'Harian 2024'!K387+'Harian 2024'!K400 -> 921 | ... U10: ='Harian 2024'!U10+'Harian 2024'!U23+'Harian 2024'!U36+'Harian 2024'!U49+'Harian 2024'!U62+'Harian 2024'!U75+'Harian 2024'!U88+'Harian 2024'!U101+'Harian 2024'!U114+'Harian 2024'!U127+'Harian 2024'!U140+'Harian 2024'!U153+'Harian 2024'!U166+'Harian 2024'!U179+'Harian 2024'!U192+'Harian 2024'!U205+'Harian 2024'!U218+'Harian 2024'!U231+'Harian 2024'!U244+'Harian 2024'!U270+'Harian 2024'!U283+'Harian 2024'!U296+'Harian 2024'!U309+'Harian 2024'!U322+'Harian 2024'!U335+'Harian 2024'!U348+'Harian 2024'!U361+'Harian 2024'!U374+'Harian 2024'!U387+'Harian 2024'!U400 -> 6180 | V10: =U10 -> 6180 | W10: =U10-V10 -> 0
C11: SLOP | D11: ='Harian 2024'!D11+'Harian 2024'!D24+'Harian 2024'!D37+'Harian 2024'!D50+'Harian 2024'!D63+'Harian 2024'!D76+'Harian 2024'!D89+'Harian 2024'!D102+'Harian 2024'!D115+'Harian 2024'!D128+'Harian 2024'!D141+'Harian 2024'!D154+'Harian 2024'!D167+'Harian 2024'!D180+'Harian 2024'!D193+'Harian 2024'!D206+'Harian 2024'!D219+'Harian 2024'!D232+'Harian 2024'!D245+'Harian 2024'!D271+'Harian 2024'!D284+'Harian 2024'!D297+'Harian 2024'!D310+'Harian 2024'!D323+'Harian 2024'!D336+'Harian 2024'!D349+'Harian 2024'!D362+'Harian 2024'!D375+'Harian 2024'!D388+'Harian 2024'!D401 -> 161 | E11: ='Harian 2024'!E11+'Harian 2024'!E24+'Harian 2024'!E37+'Harian 2024'!E50+'Harian 2024'!E63+'Harian 2024'!E76+'Harian 2024'!E89+'Harian 2024'!E102+'Harian 2024'!E115+'Harian 2024'!E128+'Harian 2024'!E141+'Harian 2024'!E154+'Harian 2024'!E167+'Harian 2024'!E180+'Harian 2024'!E193+'Harian 2024'!E206+'Harian 2024'!E219+'Harian 2024'!E232+'Harian 2024'!E245+'Harian 2024'!E271+'Harian 2024'!E284+'Harian 2024'!E297+'Harian 2024'!E310+'Harian 2024'!E323+'Harian 2024'!E336+'Harian 2024'!E349+'Harian 2024'!E362+'Harian 2024'!E375+'Harian 2024'!E388+'Harian 2024'!E401 -> 327 | F11: ='Harian 2024'!F11+'Harian 2024'!F24+'Harian 2024'!F37+'Harian 2024'!F50+'Harian 2024'!F63+'Harian 2024'!F76+'Harian 2024'!F89+'Harian 2024'!F102+'Harian 2024'!F115+'Harian 2024'!F128+'Harian 2024'!F141+'Harian 2024'!F154+'Harian 2024'!F167+'Harian 2024'!F180+'Harian 2024'!F193+'Harian 2024'!F206+'Harian 2024'!F219+'Harian 2024'!F232+'Harian 2024'!F245+'Harian 2024'!F271+'Harian 2024'!F284+'Harian 2024'!F297+'Harian 2024'!F310+'Harian 2024'!F323+'Harian 2024'!F336+'Harian 2024'!F349+'Harian 2024'!F362+'Harian 2024'!F375+'Harian 2024'!F388+'Harian 2024'!F401 -> 232 | G11: ='Harian 2024'!G11+'Harian 2024'!G24+'Harian 2024'!G37+'Harian 2024'!G50+'Harian 2024'!G63+'Harian 2024'!G76+'Harian 2024'!G89+'Harian 2024'!G102+'Harian 2024'!G115+'Harian 2024'!G128+'Harian 2024'!G141+'Harian 2024'!G154+'Harian 2024'!G167+'Harian 2024'!G180+'Harian 2024'!G193+'Harian 2024'!G206+'Harian 2024'!G219+'Harian 2024'!G232+'Harian 2024'!G245+'Harian 2024'!G271+'Harian 2024'!G284+'Harian 2024'!G297+'Harian 2024'!G310+'Harian 2024'!G323+'Harian 2024'!G336+'Harian 2024'!G349+'Harian 2024'!G362+'Harian 2024'!G375+'Harian 2024'!G388+'Harian 2024'!G401 -> 720 | H11: ='Harian 2024'!H11+'Harian 2024'!H24+'Harian 2024'!H37+'Harian 2024'!H50+'Harian 2024'!H63+'Harian 2024'!H76+'Harian 2024'!H89+'Harian 2024'!H102+'Harian 2024'!H115+'Harian 2024'!H128+'Harian 2024'!H141+'Harian 2024'!H154+'Harian 2024'!H167+'Harian 2024'!H180+'Harian 2024'!H193+'Harian 2024'!H206+'Harian 2024'!H219+'Harian 2024'!H232+'Harian 2024'!H245+'Harian 2024'!H271+'Harian 2024'!H284+'Harian 2024'!H297+'Harian 2024'!H310+'Harian 2024'!H323+'Harian 2024'!H336+'Harian 2024'!H349+'Harian 2024'!H362+'Harian 2024'!H375+'Harian 2024'!H388+'Harian 2024'!H401 -> 884 | I11: ='Harian 2024'!I11+'Harian 2024'!I24+'Harian 2024'!I37+'Harian 2024'!I50+'Harian 2024'!I63+'Harian 2024'!I76+'Harian 2024'!I89+'Harian 2024'!I102+'Harian 2024'!I115+'Harian 2024'!I128+'Harian 2024'!I141+'Harian 2024'!I154+'Harian 2024'!I167+'Harian 2024'!I180+'Harian 2024'!I193+'Harian 2024'!I206+'Harian 2024'!I219+'Harian 2024'!I232+'Harian 2024'!I245+'Harian 2024'!I271+'Harian 2024'!I284+'Harian 2024'!I297+'Harian 2024'!I310+'Harian 2024'!I323+'Harian 2024'!I336+'Harian 2024'!I349+'Harian 2024'!I362+'Harian 2024'!I375+'Harian 2024'!I388+'Harian 2024'!I401 -> 960 | J11: ='Harian 2024'!J11+'Harian 2024'!J24+'Harian 2024'!J37+'Harian 2024'!J50+'Harian 2024'!J63+'Harian 2024'!J76+'Harian 2024'!J89+'Harian 2024'!J102+'Harian 2024'!J115+'Harian 2024'!J128+'Harian 2024'!J141+'Harian 2024'!J154+'Harian 2024'!J167+'Harian 2024'!J180+'Harian 2024'!J193+'Harian 2024'!J206+'Harian 2024'!J219+'Harian 2024'!J232+'Harian 2024'!J245+'Harian 2024'!J271+'Harian 2024'!J284+'Harian 2024'!J297+'Harian 2024'!J310+'Harian 2024'!J323+'Harian 2024'!J336+'Harian 2024'!J349+'Harian 2024'!J362+'Harian 2024'!J375+'Harian 2024'!J388+'Harian 2024'!J401 -> 942 | K11: ='Harian 2024'!K11+'Harian 2024'!K24+'Harian 2024'!K37+'Harian 2024'!K50+'Harian 2024'!K63+'Harian 2024'!K76+'Harian 2024'!K89+'Harian 2024'!K102+'Harian 2024'!K115+'Harian 2024'!K128+'Harian 2024'!K141+'Harian 2024'!K154+'Harian 2024'!K167+'Harian 2024'!K180+'Harian 2024'!K193+'Harian 2024'!K206+'Harian 2024'!K219+'Harian 2024'!K232+'Harian 2024'!K245+'Harian 2024'!K271+'Harian 2024'!K284+'Harian 2024'!K297+'Harian 2024'!K310+'Harian 2024'!K323+'Harian 2024'!K336+'Harian 2024'!K349+'Harian 2024'!K362+'Harian 2024'!K375+'Harian 2024'!K388+'Harian 2024'!K401 -> 957 | ... U11: ='Harian 2024'!U11+'Harian 2024'!U24+'Harian 2024'!U37+'Harian 2024'!U50+'Harian 2024'!U63+'Harian 2024'!U76+'Harian 2024'!U89+'Harian 2024'!U102+'Harian 2024'!U115+'Harian 2024'!U128+'Harian 2024'!U141+'Harian 2024'!U154+'Harian 2024'!U167+'Harian 2024'!U180+'Harian 2024'!U193+'Harian 2024'!U206+'Harian 2024'!U219+'Harian 2024'!U232+'Harian 2024'!U245+'Harian 2024'!U271+'Harian 2024'!U284+'Harian 2024'!U297+'Harian 2024'!U310+'Harian 2024'!U323+'Harian 2024'!U336+'Harian 2024'!U349+'Harian 2024'!U362+'Harian 2024'!U375+'Harian 2024'!U388+'Harian 2024'!U401 -> 6215 | V11: =U11 -> 6215 | W11: =U11-V11 -> 0
C12: STIK | D12: ='Harian 2024'!D12+'Harian 2024'!D25+'Harian 2024'!D38+'Harian 2024'!D51+'Harian 2024'!D64+'Harian 2024'!D77+'Harian 2024'!D90+'Harian 2024'!D103+'Harian 2024'!D116+'Harian 2024'!D129+'Harian 2024'!D142+'Harian 2024'!D155+'Harian 2024'!D168+'Harian 2024'!D181+'Harian 2024'!D194+'Harian 2024'!D207+'Harian 2024'!D220+'Harian 2024'!D233+'Harian 2024'!D246+'Harian 2024'!D272+'Harian 2024'!D285+'Harian 2024'!D298+'Harian 2024'!D311+'Harian 2024'!D324+'Harian 2024'!D337+'Harian 2024'!D350+'Harian 2024'!D363+'Harian 2024'!D376+'Harian 2024'!D389+'Harian 2024'!D402 -> 124 | E12: ='Harian 2024'!E12+'Harian 2024'!E25+'Harian 2024'!E38+'Harian 2024'!E51+'Harian 2024'!E64+'Harian 2024'!E77+'Harian 2024'!E90+'Harian 2024'!E103+'Harian 2024'!E116+'Harian 2024'!E129+'Harian 2024'!E142+'Harian 2024'!E155+'Harian 2024'!E168+'Harian 2024'!E181+'Harian 2024'!E194+'Harian 2024'!E207+'Harian 2024'!E220+'Harian 2024'!E233+'Harian 2024'!E246+'Harian 2024'!E272+'Harian 2024'!E285+'Harian 2024'!E298+'Harian 2024'!E311+'Harian 2024'!E324+'Harian 2024'!E337+'Harian 2024'!E350+'Harian 2024'!E363+'Harian 2024'!E376+'Harian 2024'!E389+'Harian 2024'!E402 -> 309 | F12: ='Harian 2024'!F12+'Harian 2024'!F25+'Harian 2024'!F38+'Harian 2024'!F51+'Harian 2024'!F64+'Harian 2024'!F77+'Harian 2024'!F90+'Harian 2024'!F103+'Harian 2024'!F116+'Harian 2024'!F129+'Harian 2024'!F142+'Harian 2024'!F155+'Harian 2024'!F168+'Harian 2024'!F181+'Harian 2024'!F194+'Harian 2024'!F207+'Harian 2024'!F220+'Harian 2024'!F233+'Harian 2024'!F246+'Harian 2024'!F272+'Harian 2024'!F285+'Harian 2024'!F298+'Harian 2024'!F311+'Harian 2024'!F324+'Harian 2024'!F337+'Harian 2024'!F350+'Harian 2024'!F363+'Harian 2024'!F376+'Harian 2024'!F389+'Harian 2024'!F402 -> 203 | G12: ='Harian 2024'!G12+'Harian 2024'!G25+'Harian 2024'!G38+'Harian 2024'!G51+'Harian 2024'!G64+'Harian 2024'!G77+'Harian 2024'!G90+'Harian 2024'!G103+'Harian 2024'!G116+'Harian 2024'!G129+'Harian 2024'!G142+'Harian 2024'!G155+'Harian 2024'!G168+'Harian 2024'!G181+'Harian 2024'!G194+'Harian 2024'!G207+'Harian 2024'!G220+'Harian 2024'!G233+'Harian 2024'!G246+'Harian 2024'!G272+'Harian 2024'!G285+'Harian 2024'!G298+'Harian 2024'!G311+'Harian 2024'!G324+'Harian 2024'!G337+'Harian 2024'!G350+'Harian 2024'!G363+'Harian 2024'!G376+'Harian 2024'!G389+'Harian 2024'!G402 -> 4 | H12: ='Harian 2024'!H12+'Harian 2024'!H25+'Harian 2024'!H38+'Harian 2024'!H51+'Harian 2024'!H64+'Harian 2024'!H77+'Harian 2024'!H90+'Harian 2024'!H103+'Harian 2024'!H116+'Harian 2024'!H129+'Harian 2024'!H142+'Harian 2024'!H155+'Harian 2024'!H168+'Harian 2024'!H181+'Harian 2024'!H194+'Harian 2024'!H207+'Harian 2024'!H220+'Harian 2024'!H233+'Harian 2024'!H246+'Harian 2024'!H272+'Harian 2024'!H285+'Harian 2024'!H298+'Harian 2024'!H311+'Harian 2024'!H324+'Harian 2024'!H337+'Harian 2024'!H350+'Harian 2024'!H363+'Harian 2024'!H376+'Harian 2024'!H389+'Harian 2024'!H402 -> 0 | I12: ='Harian 2024'!I12+'Harian 2024'!I25+'Harian 2024'!I38+'Harian 2024'!I51+'Harian 2024'!I64+'Harian 2024'!I77+'Harian 2024'!I90+'Harian 2024'!I103+'Harian 2024'!I116+'Harian 2024'!I129+'Harian 2024'!I142+'Harian 2024'!I155+'Harian 2024'!I168+'Harian 2024'!I181+'Harian 2024'!I194+'Harian 2024'!I207+'Harian 2024'!I220+'Harian 2024'!I233+'Harian 2024'!I246+'Harian 2024'!I272+'Harian 2024'!I285+'Harian 2024'!I298+'Harian 2024'!I311+'Harian 2024'!I324+'Harian 2024'!I337+'Harian 2024'!I350+'Harian 2024'!I363+'Harian 2024'!I376+'Harian 2024'!I389+'Harian 2024'!I402 -> 0 | J12: ='Harian 2024'!J12+'Harian 2024'!J25+'Harian 2024'!J38+'Harian 2024'!J51+'Harian 2024'!J64+'Harian 2024'!J77+'Harian 2024'!J90+'Harian 2024'!J103+'Harian 2024'!J116+'Harian 2024'!J129+'Harian 2024'!J142+'Harian 2024'!J155+'Harian 2024'!J168+'Harian 2024'!J181+'Harian 2024'!J194+'Harian 2024'!J207+'Harian 2024'!J220+'Harian 2024'!J233+'Harian 2024'!J246+'Harian 2024'!J272+'Harian 2024'!J285+'Harian 2024'!J298+'Harian 2024'!J311+'Harian 2024'!J324+'Harian 2024'!J337+'Harian 2024'!J350+'Harian 2024'!J363+'Harian 2024'!J376+'Harian 2024'!J389+'Harian 2024'!J402 -> 0 | K12: ='Harian 2024'!K12+'Harian 2024'!K25+'Harian 2024'!K38+'Harian 2024'!K51+'Harian 2024'!K64+'Harian 2024'!K77+'Harian 2024'!K90+'Harian 2024'!K103+'Harian 2024'!K116+'Harian 2024'!K129+'Harian 2024'!K142+'Harian 2024'!K155+'Harian 2024'!K168+'Harian 2024'!K181+'Harian 2024'!K194+'Harian 2024'!K207+'Harian 2024'!K220+'Harian 2024'!K233+'Harian 2024'!K246+'Harian 2024'!K272+'Harian 2024'!K285+'Harian 2024'!K298+'Harian 2024'!K311+'Harian 2024'!K324+'Harian 2024'!K337+'Harian 2024'!K350+'Harian 2024'!K363+'Harian 2024'!K376+'Harian 2024'!K389+'Harian 2024'!K402 -> 0 | ... U12: ='Harian 2024'!U12+'Harian 2024'!U25+'Harian 2024'!U38+'Harian 2024'!U51+'Harian 2024'!U64+'Harian 2024'!U77+'Harian 2024'!U90+'Harian 2024'!U103+'Harian 2024'!U116+'Harian 2024'!U129+'Harian 2024'!U142+'Harian 2024'!U155+'Harian 2024'!U168+'Harian 2024'!U181+'Harian 2024'!U194+'Harian 2024'!U207+'Harian 2024'!U220+'Harian 2024'!U233+'Harian 2024'!U246+'Harian 2024'!U272+'Harian 2024'!U285+'Harian 2024'!U298+'Harian 2024'!U311+'Harian 2024'!U324+'Harian 2024'!U337+'Harian 2024'!U350+'Harian 2024'!U363+'Harian 2024'!U376+'Harian 2024'!U389+'Harian 2024'!U402 -> 826 | V12: =U12 -> 826 | W12: =U12-V12 -> 0
C13: PERLAK | D13: ='Harian 2024'!D13+'Harian 2024'!D26+'Harian 2024'!D39+'Harian 2024'!D52+'Harian 2024'!D65+'Harian 2024'!D78+'Harian 2024'!D91+'Harian 2024'!D104+'Harian 2024'!D117+'Harian 2024'!D130+'Harian 2024'!D143+'Harian 2024'!D156+'Harian 2024'!D169+'Harian 2024'!D182+'Harian 2024'!D195+'Harian 2024'!D208+'Harian 2024'!D221+'Harian 2024'!D234+'Harian 2024'!D247+'Harian 2024'!D273+'Harian 2024'!D286+'Harian 2024'!D299+'Harian 2024'!D312+'Harian 2024'!D325+'Harian 2024'!D338+'Harian 2024'!D351+'Harian 2024'!D364+'Harian 2024'!D377+'Harian 2024'!D390+'Harian 2024'!D403 -> 93 | E13: ='Harian 2024'!E13+'Harian 2024'!E26+'Harian 2024'!E39+'Harian 2024'!E52+'Harian 2024'!E65+'Harian 2024'!E78+'Harian 2024'!E91+'Harian 2024'!E104+'Harian 2024'!E117+'Harian 2024'!E130+'Harian 2024'!E143+'Harian 2024'!E156+'Harian 2024'!E169+'Harian 2024'!E182+'Harian 2024'!E195+'Harian 2024'!E208+'Harian 2024'!E221+'Harian 2024'!E234+'Harian 2024'!E247+'Harian 2024'!E273+'Harian 2024'!E286+'Harian 2024'!E299+'Harian 2024'!E312+'Harian 2024'!E325+'Harian 2024'!E338+'Harian 2024'!E351+'Harian 2024'!E364+'Harian 2024'!E377+'Harian 2024'!E390+'Harian 2024'!E403 -> 213 | F13: ='Harian 2024'!F13+'Harian 2024'!F26+'Harian 2024'!F39+'Harian 2024'!F52+'Harian 2024'!F65+'Harian 2024'!F78+'Harian 2024'!F91+'Harian 2024'!F104+'Harian 2024'!F117+'Harian 2024'!F130+'Harian 2024'!F143+'Harian 2024'!F156+'Harian 2024'!F169+'Harian 2024'!F182+'Harian 2024'!F195+'Harian 2024'!F208+'Harian 2024'!F221+'Harian 2024'!F234+'Harian 2024'!F247+'Harian 2024'!F273+'Harian 2024'!F286+'Harian 2024'!F299+'Harian 2024'!F312+'Harian 2024'!F325+'Harian 2024'!F338+'Harian 2024'!F351+'Harian 2024'!F364+'Harian 2024'!F377+'Harian 2024'!F390+'Harian 2024'!F403 -> 151 | G13: ='Harian 2024'!G13+'Harian 2024'!G26+'Harian 2024'!G39+'Harian 2024'!G52+'Harian 2024'!G65+'Harian 2024'!G78+'Harian 2024'!G91+'Harian 2024'!G104+'Harian 2024'!G117+'Harian 2024'!G130+'Harian 2024'!G143+'Harian 2024'!G156+'Harian 2024'!G169+'Harian 2024'!G182+'Harian 2024'!G195+'Harian 2024'!G208+'Harian 2024'!G221+'Harian 2024'!G234+'Harian 2024'!G247+'Harian 2024'!G273+'Harian 2024'!G286+'Harian 2024'!G299+'Harian 2024'!G312+'Harian 2024'!G325+'Harian 2024'!G338+'Harian 2024'!G351+'Harian 2024'!G364+'Harian 2024'!G377+'Harian 2024'!G390+'Harian 2024'!G403 -> 2 | H13: ='Harian 2024'!H13+'Harian 2024'!H26+'Harian 2024'!H39+'Harian 2024'!H52+'Harian 2024'!H65+'Harian 2024'!H78+'Harian 2024'!H91+'Harian 2024'!H104+'Harian 2024'!H117+'Harian 2024'!H130+'Harian 2024'!H143+'Harian 2024'!H156+'Harian 2024'!H169+'Harian 2024'!H182+'Harian 2024'!H195+'Harian 2024'!H208+'Harian 2024'!H221+'Harian 2024'!H234+'Harian 2024'!H247+'Harian 2024'!H273+'Harian 2024'!H286+'Harian 2024'!H299+'Harian 2024'!H312+'Harian 2024'!H325+'Harian 2024'!H338+'Harian 2024'!H351+'Harian 2024'!H364+'Harian 2024'!H377+'Harian 2024'!H390+'Harian 2024'!H403 -> 0 | I13: ='Harian 2024'!I13+'Harian 2024'!I26+'Harian 2024'!I39+'Harian 2024'!I52+'Harian 2024'!I65+'Harian 2024'!I78+'Harian 2024'!I91+'Harian 2024'!I104+'Harian 2024'!I117+'Harian 2024'!I130+'Harian 2024'!I143+'Harian 2024'!I156+'Harian 2024'!I169+'Harian 2024'!I182+'Harian 2024'!I195+'Harian 2024'!I208+'Harian 2024'!I221+'Harian 2024'!I234+'Harian 2024'!I247+'Harian 2024'!I273+'Harian 2024'!I286+'Harian 2024'!I299+'Harian 2024'!I312+'Harian 2024'!I325+'Harian 2024'!I338+'Harian 2024'!I351+'Harian 2024'!I364+'Harian 2024'!I377+'Harian 2024'!I390+'Harian 2024'!I403 -> 0 | J13: ='Harian 2024'!J13+'Harian 2024'!J26+'Harian 2024'!J39+'Harian 2024'!J52+'Harian 2024'!J65+'Harian 2024'!J78+'Harian 2024'!J91+'Harian 2024'!J104+'Harian 2024'!J117+'Harian 2024'!J130+'Harian 2024'!J143+'Harian 2024'!J156+'Harian 2024'!J169+'Harian 2024'!J182+'Harian 2024'!J195+'Harian 2024'!J208+'Harian 2024'!J221+'Harian 2024'!J234+'Harian 2024'!J247+'Harian 2024'!J273+'Harian 2024'!J286+'Harian 2024'!J299+'Harian 2024'!J312+'Harian 2024'!J325+'Harian 2024'!J338+'Harian 2024'!J351+'Harian 2024'!J364+'Harian 2024'!J377+'Harian 2024'!J390+'Harian 2024'!J403 -> 0 | K13: ='Harian 2024'!K13+'Harian 2024'!K26+'Harian 2024'!K39+'Harian 2024'!K52+'Harian 2024'!K65+'Harian 2024'!K78+'Harian 2024'!K91+'Harian 2024'!K104+'Harian 2024'!K117+'Harian 2024'!K130+'Harian 2024'!K143+'Harian 2024'!K156+'Harian 2024'!K169+'Harian 2024'!K182+'Harian 2024'!K195+'Harian 2024'!K208+'Harian 2024'!K221+'Harian 2024'!K234+'Harian 2024'!K247+'Harian 2024'!K273+'Harian 2024'!K286+'Harian 2024'!K299+'Harian 2024'!K312+'Harian 2024'!K325+'Harian 2024'!K338+'Harian 2024'!K351+'Harian 2024'!K364+'Harian 2024'!K377+'Harian 2024'!K390+'Harian 2024'!K403 -> 0 | ... U13: ='Harian 2024'!U13+'Harian 2024'!U26+'Harian 2024'!U39+'Harian 2024'!U52+'Harian 2024'!U65+'Harian 2024'!U78+'Harian 2024'!U91+'Harian 2024'!U104+'Harian 2024'!U117+'Harian 2024'!U130+'Harian 2024'!U143+'Harian 2024'!U156+'Harian 2024'!U169+'Harian 2024'!U182+'Harian 2024'!U195+'Harian 2024'!U208+'Harian 2024'!U221+'Harian 2024'!U234+'Harian 2024'!U247+'Harian 2024'!U273+'Harian 2024'!U286+'Harian 2024'!U299+'Harian 2024'!U312+'Harian 2024'!U325+'Harian 2024'!U338+'Harian 2024'!U351+'Harian 2024'!U364+'Harian 2024'!U377+'Harian 2024'!U390+'Harian 2024'!U403 -> 657 | V13: =U13 -> 657 | W13: =U13-V13 -> 0
C14: DLL | D14: ='Harian 2024'!D14+'Harian 2024'!D27+'Harian 2024'!D40+'Harian 2024'!D53+'Harian 2024'!D66+'Harian 2024'!D79+'Harian 2024'!D92+'Harian 2024'!D105+'Harian 2024'!D118+'Harian 2024'!D131+'Harian 2024'!D144+'Harian 2024'!D157+'Harian 2024'!D170+'Harian 2024'!D183+'Harian 2024'!D196+'Harian 2024'!D209+'Harian 2024'!D222+'Harian 2024'!D235+'Harian 2024'!D248+'Harian 2024'!D274+'Harian 2024'!D287+'Harian 2024'!D300+'Harian 2024'!D313+'Harian 2024'!D326+'Harian 2024'!D339+'Harian 2024'!D352+'Harian 2024'!D365+'Harian 2024'!D378+'Harian 2024'!D391+'Harian 2024'!D404 -> 25 | E14: ='Harian 2024'!E14+'Harian 2024'!E27+'Harian 2024'!E40+'Harian 2024'!E53+'Harian 2024'!E66+'Harian 2024'!E79+'Harian 2024'!E92+'Harian 2024'!E105+'Harian 2024'!E118+'Harian 2024'!E131+'Harian 2024'!E144+'Harian 2024'!E157+'Harian 2024'!E170+'Harian 2024'!E183+'Harian 2024'!E196+'Harian 2024'!E209+'Harian 2024'!E222+'Harian 2024'!E235+'Harian 2024'!E248+'Harian 2024'!E274+'Harian 2024'!E287+'Harian 2024'!E300+'Harian 2024'!E313+'Harian 2024'!E326+'Harian 2024'!E339+'Harian 2024'!E352+'Harian 2024'!E365+'Harian 2024'!E378+'Harian 2024'!E391+'Harian 2024'!E404 -> 75 | F14: ='Harian 2024'!F14+'Harian 2024'!F27+'Harian 2024'!F40+'Harian 2024'!F53+'Harian 2024'!F66+'Harian 2024'!F79+'Harian 2024'!F92+'Harian 2024'!F105+'Harian 2024'!F118+'Harian 2024'!F131+'Harian 2024'!F144+'Harian 2024'!F157+'Harian 2024'!F170+'Harian 2024'!F183+'Harian 2024'!F196+'Harian 2024'!F209+'Harian 2024'!F222+'Harian 2024'!F235+'Harian 2024'!F248+'Harian 2024'!F274+'Harian 2024'!F287+'Harian 2024'!F300+'Harian 2024'!F313+'Harian 2024'!F326+'Harian 2024'!F339+'Harian 2024'!F352+'Harian 2024'!F365+'Harian 2024'!F378+'Harian 2024'!F391+'Harian 2024'!F404 -> 42 | G14: ='Harian 2024'!G14+'Harian 2024'!G27+'Harian 2024'!G40+'Harian 2024'!G53+'Harian 2024'!G66+'Harian 2024'!G79+'Harian 2024'!G92+'Harian 2024'!G105+'Harian 2024'!G118+'Harian 2024'!G131+'Harian 2024'!G144+'Harian 2024'!G157+'Harian 2024'!G170+'Harian 2024'!G183+'Harian 2024'!G196+'Harian 2024'!G209+'Harian 2024'!G222+'Harian 2024'!G235+'Harian 2024'!G248+'Harian 2024'!G274+'Harian 2024'!G287+'Harian 2024'!G300+'Harian 2024'!G313+'Harian 2024'!G326+'Harian 2024'!G339+'Harian 2024'!G352+'Harian 2024'!G365+'Harian 2024'!G378+'Harian 2024'!G391+'Harian 2024'!G404 -> 252 | H14: ='Harian 2024'!H14+'Harian 2024'!H27+'Harian 2024'!H40+'Harian 2024'!H53+'Harian 2024'!H66+'Harian 2024'!H79+'Harian 2024'!H92+'Harian 2024'!H105+'Harian 2024'!H118+'Harian 2024'!H131+'Harian 2024'!H144+'Harian 2024'!H157+'Harian 2024'!H170+'Harian 2024'!H183+'Harian 2024'!H196+'Harian 2024'!H209+'Harian 2024'!H222+'Harian 2024'!H235+'Harian 2024'!H248+'Harian 2024'!H274+'Harian 2024'!H287+'Harian 2024'!H300+'Harian 2024'!H313+'Harian 2024'!H326+'Harian 2024'!H339+'Harian 2024'!H352+'Harian 2024'!H365+'Harian 2024'!H378+'Harian 2024'!H391+'Harian 2024'!H404 -> 429 | I14: ='Harian 2024'!I14+'Harian 2024'!I27+'Harian 2024'!I40+'Harian 2024'!I53+'Harian 2024'!I66+'Harian 2024'!I79+'Harian 2024'!I92+'Harian 2024'!I105+'Harian 2024'!I118+'Harian 2024'!I131+'Harian 2024'!I144+'Harian 2024'!I157+'Harian 2024'!I170+'Harian 2024'!I183+'Harian 2024'!I196+'Harian 2024'!I209+'Harian 2024'!I222+'Harian 2024'!I235+'Harian 2024'!I248+'Harian 2024'!I274+'Harian 2024'!I287+'Harian 2024'!I300+'Harian 2024'!I313+'Harian 2024'!I326+'Harian 2024'!I339+'Harian 2024'!I352+'Harian 2024'!I365+'Harian 2024'!I378+'Harian 2024'!I391+'Harian 2024'!I404 -> 297 | J14: ='Harian 2024'!J14+'Harian 2024'!J27+'Harian 2024'!J40+'Harian 2024'!J53+'Harian 2024'!J66+'Harian 2024'!J79+'Harian 2024'!J92+'Harian 2024'!J105+'Harian 2024'!J118+'Harian 2024'!J131+'Harian 2024'!J144+'Harian 2024'!J157+'Harian 2024'!J170+'Harian 2024'!J183+'Harian 2024'!J196+'Harian 2024'!J209+'Harian 2024'!J222+'Harian 2024'!J235+'Harian 2024'!J248+'Harian 2024'!J274+'Harian 2024'!J287+'Harian 2024'!J300+'Harian 2024'!J313+'Harian 2024'!J326+'Harian 2024'!J339+'Harian 2024'!J352+'Harian 2024'!J365+'Harian 2024'!J378+'Harian 2024'!J391+'Harian 2024'!J404 -> 309 | K14: ='Harian 2024'!K14+'Harian 2024'!K27+'Harian 2024'!K40+'Harian 2024'!K53+'Harian 2024'!K66+'Harian 2024'!K79+'Harian 2024'!K92+'Harian 2024'!K105+'Harian 2024'!K118+'Harian 2024'!K131+'Harian 2024'!K144+'Harian 2024'!K157+'Harian 2024'!K170+'Harian 2024'!K183+'Harian 2024'!K196+'Harian 2024'!K209+'Harian 2024'!K222+'Harian 2024'!K235+'Harian 2024'!K248+'Harian 2024'!K274+'Harian 2024'!K287+'Harian 2024'!K300+'Harian 2024'!K313+'Harian 2024'!K326+'Harian 2024'!K339+'Harian 2024'!K352+'Harian 2024'!K365+'Harian 2024'!K378+'Harian 2024'!K391+'Harian 2024'!K404 -> 296 | ... U14: ='Harian 2024'!U14+'Harian 2024'!U27+'Harian 2024'!U40+'Harian 2024'!U53+'Harian 2024'!U66+'Harian 2024'!U79+'Harian 2024'!U92+'Harian 2024'!U105+'Harian 2024'!U118+'Harian 2024'!U131+'Harian 2024'!U144+'Harian 2024'!U157+'Harian 2024'!U170+'Harian 2024'!U183+'Harian 2024'!U196+'Harian 2024'!U209+'Harian 2024'!U222+'Harian 2024'!U235+'Harian 2024'!U248+'Harian 2024'!U274+'Harian 2024'!U287+'Harian 2024'!U300+'Harian 2024'!U313+'Harian 2024'!U326+'Harian 2024'!U339+'Harian 2024'!U352+'Harian 2024'!U365+'Harian 2024'!U378+'Harian 2024'!U391+'Harian 2024'!U404 -> 2687 | V14: =U14 -> 2687 | W14: =U14-V14 -> 0
C15: SUB JUMLAH | D15: =SUM(D6:D14) -> 734 | E15: =SUM(E6:E14) -> 1574 | F15: =SUM(F6:F14) -> 1083 | G15: =SUM(G6:G14) -> 4182 | H15: =SUM(H6:H14) -> 4953 | I15: =SUM(I6:I14) -> 5149 | J15: =SUM(J6:J14) -> 5110 | K15: =SUM(K6:K14) -> 5425 | ... U15: =SUM(U6:U14) -> 35968 | V15: =U15 -> 35968 | W15: =U15-V15 -> 0
A18: PENGELOLAAN LINEN INSTALASI LAUNDRY (POTONG)
A19: RSJD Dr RM SOEDJARWADI PROVINSI JAWA TENGAH
A20: BULAN FEBRUARI 2026
A22: NO | B22: BULAN | C22: JENIS LINEN | D22: =D5 -> ANGGREK | E22: =E5 -> BOUGENVIL | F22: =F5 -> CAMELIA II | G22: =G5 -> DEWANDARU | H22: =H5 -> EDELWEIS | I22: =I5 -> FLAMBOYAN | J22: =J5 -> GERANIUM | K22: =K5 -> HELIKONIA | ... U22: =U5 -> Ʃ Masuk | V22: Ʃ Kirim | W22: SELISIH
B23: FEBRUARI | C23: BAJU | D23: ='Harian 2024'!D419+'Harian 2024'!D432+'Harian 2024'!D445+'Harian 2024'!D458+'Harian 2024'!D471+'Harian 2024'!D484+'Harian 2024'!D497+'Harian 2024'!D510+'Harian 2024'!D523+'Harian 2024'!D536+'Harian 2024'!D549+'Harian 2024'!D562+'Harian 2024'!D575+'Harian 2024'!D588+'Harian 2024'!D601+'Harian 2024'!D614+'Harian 2024'!D627+'Harian 2024'!D640+'Harian 2024'!D653+'Harian 2024'!D666+'Harian 2024'!D679+'Harian 2024'!D692+'Harian 2024'!D705+'Harian 2024'!D718+'Harian 2024'!D731+'Harian 2024'!D744+'Harian 2024'!D757+'Harian 2024'!D770 -> 20 | E23: ='Harian 2024'!E419+'Harian 2024'!E432+'Harian 2024'!E445+'Harian 2024'!E458+'Harian 2024'!E471+'Harian 2024'!E484+'Harian 2024'!E497+'Harian 2024'!E510+'Harian 2024'!E523+'Harian 2024'!E536+'Harian 2024'!E549+'Harian 2024'!E562+'Harian 2024'!E575+'Harian 2024'!E588+'Harian 2024'!E601+'Harian 2024'!E614+'Harian 2024'!E627+'Harian 2024'!E640+'Harian 2024'!E653+'Harian 2024'!E666+'Harian 2024'!E679+'Harian 2024'!E692+'Harian 2024'!E705+'Harian 2024'!E718+'Harian 2024'!E731+'Harian 2024'!E744+'Harian 2024'!E757+'Harian 2024'!E770 -> 0 | F23: ='Harian 2024'!F419+'Harian 2024'!F432+'Harian 2024'!F445+'Harian 2024'!F458+'Harian 2024'!F471+'Harian 2024'!F484+'Harian 2024'!F497+'Harian 2024'!F510+'Harian 2024'!F523+'Harian 2024'!F536+'Harian 2024'!F549+'Harian 2024'!F562+'Harian 2024'!F575+'Harian 2024'!F588+'Harian 2024'!F601+'Harian 2024'!F614+'Harian 2024'!F627+'Harian 2024'!F640+'Harian 2024'!F653+'Harian 2024'!F666+'Harian 2024'!F679+'Harian 2024'!F692+'Harian 2024'!F705+'Harian 2024'!F718+'Harian 2024'!F731+'Harian 2024'!F744+'Harian 2024'!F757+'Harian 2024'!F770 -> 6 | G23: ='Harian 2024'!G419+'Harian 2024'!G432+'Harian 2024'!G445+'Harian 2024'!G458+'Harian 2024'!G471+'Harian 2024'!G484+'Harian 2024'!G497+'Harian 2024'!G510+'Harian 2024'!G523+'Harian 2024'!G536+'Harian 2024'!G549+'Harian 2024'!G562+'Harian 2024'!G575+'Harian 2024'!G588+'Harian 2024'!G601+'Harian 2024'!G614+'Harian 2024'!G627+'Harian 2024'!G640+'Harian 2024'!G653+'Harian 2024'!G666+'Harian 2024'!G679+'Harian 2024'!G692+'Harian 2024'!G705+'Harian 2024'!G718+'Harian 2024'!G731+'Harian 2024'!G744+'Harian 2024'!G757+'Harian 2024'!G770 -> 582 | H23: ='Harian 2024'!H419+'Harian 2024'!H432+'Harian 2024'!H445+'Harian 2024'!H458+'Harian 2024'!H471+'Harian 2024'!H484+'Harian 2024'!H497+'Harian 2024'!H510+'Harian 2024'!H523+'Harian 2024'!H536+'Harian 2024'!H549+'Harian 2024'!H562+'Harian 2024'!H575+'Harian 2024'!H588+'Harian 2024'!H601+'Harian 2024'!H614+'Harian 2024'!H627+'Harian 2024'!H640+'Harian 2024'!H653+'Harian 2024'!H666+'Harian 2024'!H679+'Harian 2024'!H692+'Harian 2024'!H705+'Harian 2024'!H718+'Harian 2024'!H731+'Harian 2024'!H744+'Harian 2024'!H757+'Harian 2024'!H770 -> 650 | I23: ='Harian 2024'!I419+'Harian 2024'!I432+'Harian 2024'!I445+'Harian 2024'!I458+'Harian 2024'!I471+'Harian 2024'!I484+'Harian 2024'!I497+'Harian 2024'!I510+'Harian 2024'!I523+'Harian 2024'!I536+'Harian 2024'!I549+'Harian 2024'!I562+'Harian 2024'!I575+'Harian 2024'!I588+'Harian 2024'!I601+'Harian 2024'!I614+'Harian 2024'!I627+'Harian 2024'!I640+'Harian 2024'!I653+'Harian 2024'!I666+'Harian 2024'!I679+'Harian 2024'!I692+'Harian 2024'!I705+'Harian 2024'!I718+'Harian 2024'!I731+'Harian 2024'!I744+'Harian 2024'!I757+'Harian 2024'!I770 -> 802 | J23: ='Harian 2024'!J419+'Harian 2024'!J432+'Harian 2024'!J445+'Harian 2024'!J458+'Harian 2024'!J471+'Harian 2024'!J484+'Harian 2024'!J497+'Harian 2024'!J510+'Harian 2024'!J523+'Harian 2024'!J536+'Harian 2024'!J549+'Harian 2024'!J562+'Harian 2024'!J575+'Harian 2024'!J588+'Harian 2024'!J601+'Harian 2024'!J614+'Harian 2024'!J627+'Harian 2024'!J640+'Harian 2024'!J653+'Harian 2024'!J666+'Harian 2024'!J679+'Harian 2024'!J692+'Harian 2024'!J705+'Harian 2024'!J718+'Harian 2024'!J731+'Harian 2024'!J744+'Harian 2024'!J757+'Harian 2024'!J770 -> 744 | K23: ='Harian 2024'!K419+'Harian 2024'!K432+'Harian 2024'!K445+'Harian 2024'!K458+'Harian 2024'!K471+'Harian 2024'!K484+'Harian 2024'!K497+'Harian 2024'!K510+'Harian 2024'!K523+'Harian 2024'!K536+'Harian 2024'!K549+'Harian 2024'!K562+'Harian 2024'!K575+'Harian 2024'!K588+'Harian 2024'!K601+'Harian 2024'!K614+'Harian 2024'!K627+'Harian 2024'!K640+'Harian 2024'!K653+'Harian 2024'!K666+'Harian 2024'!K679+'Harian 2024'!K692+'Harian 2024'!K705+'Harian 2024'!K718+'Harian 2024'!K731+'Harian 2024'!K744+'Harian 2024'!K757+'Harian 2024'!K770 -> 849 | ... U23: ='Harian 2024'!U419+'Harian 2024'!U432+'Harian 2024'!U445+'Harian 2024'!U458+'Harian 2024'!U471+'Harian 2024'!U484+'Harian 2024'!U497+'Harian 2024'!U510+'Harian 2024'!U523+'Harian 2024'!U536+'Harian 2024'!U549+'Harian 2024'!U562+'Harian 2024'!U575+'Harian 2024'!U588+'Harian 2024'!U601+'Harian 2024'!U614+'Harian 2024'!U627+'Harian 2024'!U640+'Harian 2024'!U653+'Harian 2024'!U666+'Harian 2024'!U679+'Harian 2024'!U692+'Harian 2024'!U705+'Harian 2024'!U718+'Harian 2024'!U731+'Harian 2024'!U744+'Harian 2024'!U757+'Harian 2024'!U770 -> 4898 | V23: =U23 -> 4898 | W23: =U23-V23 -> 0
